2025-08-25 12:38:10,250 - publishers.twitter - ERROR - twitter.py:46 - Twitter api_key not configured
2025-08-25 12:38:10,984 - web_interface - ERROR - web_interface.py:52 - Error loading dashboard: No filter named 'tojsonfilter'.
2025-08-25 12:38:11,001 - web_interface - ERROR - app.py:875 - Exception on / [GET]
Traceback (most recent call last):
  File "/home/runner/workspace/web_interface.py", line 47, in dashboard
    return render_template('dashboard.html',
           ^^^^^^^^^^^^^^^^^^^^^^^^^^^^^^^^^
  File "/home/runner/workspace/.pythonlibs/lib/python3.11/site-packages/flask/templating.py", line 149, in render_template
    template = app.jinja_env.get_or_select_template(template_name_or_list)
               ^^^^^^^^^^^^^^^^^^^^^^^^^^^^^^^^^^^^^^^^^^^^^^^^^^^^^^^^^^^
  File "/home/runner/workspace/.pythonlibs/lib/python3.11/site-packages/jinja2/environment.py", line 1087, in get_or_select_template
    return self.get_template(template_name_or_list, parent, globals)
           ^^^^^^^^^^^^^^^^^^^^^^^^^^^^^^^^^^^^^^^^^^^^^^^^^^^^^^^^^
  File "/home/runner/workspace/.pythonlibs/lib/python3.11/site-packages/jinja2/environment.py", line 1016, in get_template
    return self._load_template(name, globals)
           ^^^^^^^^^^^^^^^^^^^^^^^^^^^^^^^^^^
  File "/home/runner/workspace/.pythonlibs/lib/python3.11/site-packages/jinja2/environment.py", line 975, in _load_template
    template = self.loader.load(self, name, self.make_globals(globals))
               ^^^^^^^^^^^^^^^^^^^^^^^^^^^^^^^^^^^^^^^^^^^^^^^^^^^^^^^^
  File "/home/runner/workspace/.pythonlibs/lib/python3.11/site-packages/jinja2/loaders.py", line 138, in load
    code = environment.compile(source, name, filename)
           ^^^^^^^^^^^^^^^^^^^^^^^^^^^^^^^^^^^^^^^^^^^
  File "/home/runner/workspace/.pythonlibs/lib/python3.11/site-packages/jinja2/environment.py", line 771, in compile
    self.handle_exception(source=source_hint)
  File "/home/runner/workspace/.pythonlibs/lib/python3.11/site-packages/jinja2/environment.py", line 942, in handle_exception
    raise rewrite_traceback_stack(source=source)
  File "/home/runner/workspace/templates/dashboard.html", line 364, in template
    const severityData = {{ stats.get('by_severity', {}) | tojsonfilter | safe }};
    ^^^^^^^^^^^^^^^^^^^^^^^^^
jinja2.exceptions.TemplateAssertionError: No filter named 'tojsonfilter'.

During handling of the above exception, another exception occurred:

Traceback (most recent call last):
  File "/home/runner/workspace/.pythonlibs/lib/python3.11/site-packages/flask/app.py", line 1511, in wsgi_app
    response = self.full_dispatch_request()
               ^^^^^^^^^^^^^^^^^^^^^^^^^^^^
  File "/home/runner/workspace/.pythonlibs/lib/python3.11/site-packages/flask/app.py", line 919, in full_dispatch_request
    rv = self.handle_user_exception(e)
         ^^^^^^^^^^^^^^^^^^^^^^^^^^^^^
  File "/home/runner/workspace/.pythonlibs/lib/python3.11/site-packages/flask/app.py", line 917, in full_dispatch_request
    rv = self.dispatch_request()
         ^^^^^^^^^^^^^^^^^^^^^^^
  File "/home/runner/workspace/.pythonlibs/lib/python3.11/site-packages/flask/app.py", line 902, in dispatch_request
    return self.ensure_sync(self.view_functions[rule.endpoint])(**view_args)  # type: ignore[no-any-return]
           ^^^^^^^^^^^^^^^^^^^^^^^^^^^^^^^^^^^^^^^^^^^^^^^^^^^^^^^^^^^^^^^^^
  File "/home/runner/workspace/web_interface.py", line 53, in dashboard
    return render_template('dashboard.html',
           ^^^^^^^^^^^^^^^^^^^^^^^^^^^^^^^^^
  File "/home/runner/workspace/.pythonlibs/lib/python3.11/site-packages/flask/templating.py", line 149, in render_template
    template = app.jinja_env.get_or_select_template(template_name_or_list)
               ^^^^^^^^^^^^^^^^^^^^^^^^^^^^^^^^^^^^^^^^^^^^^^^^^^^^^^^^^^^
  File "/home/runner/workspace/.pythonlibs/lib/python3.11/site-packages/jinja2/environment.py", line 1087, in get_or_select_template
    return self.get_template(template_name_or_list, parent, globals)
           ^^^^^^^^^^^^^^^^^^^^^^^^^^^^^^^^^^^^^^^^^^^^^^^^^^^^^^^^^
  File "/home/runner/workspace/.pythonlibs/lib/python3.11/site-packages/jinja2/environment.py", line 1016, in get_template
    return self._load_template(name, globals)
           ^^^^^^^^^^^^^^^^^^^^^^^^^^^^^^^^^^
  File "/home/runner/workspace/.pythonlibs/lib/python3.11/site-packages/jinja2/environment.py", line 975, in _load_template
    template = self.loader.load(self, name, self.make_globals(globals))
               ^^^^^^^^^^^^^^^^^^^^^^^^^^^^^^^^^^^^^^^^^^^^^^^^^^^^^^^^
  File "/home/runner/workspace/.pythonlibs/lib/python3.11/site-packages/jinja2/loaders.py", line 138, in load
    code = environment.compile(source, name, filename)
           ^^^^^^^^^^^^^^^^^^^^^^^^^^^^^^^^^^^^^^^^^^^
  File "/home/runner/workspace/.pythonlibs/lib/python3.11/site-packages/jinja2/environment.py", line 771, in compile
    self.handle_exception(source=source_hint)
  File "/home/runner/workspace/.pythonlibs/lib/python3.11/site-packages/jinja2/environment.py", line 942, in handle_exception
    raise rewrite_traceback_stack(source=source)
  File "/home/runner/workspace/templates/dashboard.html", line 364, in template
    const severityData = {{ stats.get('by_severity', {}) | tojsonfilter | safe }};
    ^^^^^^^^^^^^^^^^^^^^^^^^^
jinja2.exceptions.TemplateAssertionError: No filter named 'tojsonfilter'.
2025-08-25 12:38:11,007 - web_interface - ERROR - web_interface.py:417 - Internal server error: 500 Internal Server Error: The server encountered an internal error and was unable to complete your request. Either the server is overloaded or there is an error in the application.
2025-08-25 12:38:11,065 - werkzeug - ERROR - _internal.py:97 - Error on request:
Traceback (most recent call last):
  File "/home/runner/workspace/web_interface.py", line 47, in dashboard
    return render_template('dashboard.html',
           ^^^^^^^^^^^^^^^^^^^^^^^^^^^^^^^^^
  File "/home/runner/workspace/.pythonlibs/lib/python3.11/site-packages/flask/templating.py", line 149, in render_template
    template = app.jinja_env.get_or_select_template(template_name_or_list)
               ^^^^^^^^^^^^^^^^^^^^^^^^^^^^^^^^^^^^^^^^^^^^^^^^^^^^^^^^^^^
  File "/home/runner/workspace/.pythonlibs/lib/python3.11/site-packages/jinja2/environment.py", line 1087, in get_or_select_template
    return self.get_template(template_name_or_list, parent, globals)
           ^^^^^^^^^^^^^^^^^^^^^^^^^^^^^^^^^^^^^^^^^^^^^^^^^^^^^^^^^
  File "/home/runner/workspace/.pythonlibs/lib/python3.11/site-packages/jinja2/environment.py", line 1016, in get_template
    return self._load_template(name, globals)
           ^^^^^^^^^^^^^^^^^^^^^^^^^^^^^^^^^^
  File "/home/runner/workspace/.pythonlibs/lib/python3.11/site-packages/jinja2/environment.py", line 975, in _load_template
    template = self.loader.load(self, name, self.make_globals(globals))
               ^^^^^^^^^^^^^^^^^^^^^^^^^^^^^^^^^^^^^^^^^^^^^^^^^^^^^^^^
  File "/home/runner/workspace/.pythonlibs/lib/python3.11/site-packages/jinja2/loaders.py", line 138, in load
    code = environment.compile(source, name, filename)
           ^^^^^^^^^^^^^^^^^^^^^^^^^^^^^^^^^^^^^^^^^^^
  File "/home/runner/workspace/.pythonlibs/lib/python3.11/site-packages/jinja2/environment.py", line 771, in compile
    self.handle_exception(source=source_hint)
  File "/home/runner/workspace/.pythonlibs/lib/python3.11/site-packages/jinja2/environment.py", line 942, in handle_exception
    raise rewrite_traceback_stack(source=source)
  File "/home/runner/workspace/templates/dashboard.html", line 364, in template
    const severityData = {{ stats.get('by_severity', {}) | tojsonfilter | safe }};
jinja2.exceptions.TemplateAssertionError: No filter named 'tojsonfilter'.

During handling of the above exception, another exception occurred:

Traceback (most recent call last):
  File "/home/runner/workspace/.pythonlibs/lib/python3.11/site-packages/flask/app.py", line 1511, in wsgi_app
    response = self.full_dispatch_request()
               ^^^^^^^^^^^^^^^^^^^^^^^^^^^^
  File "/home/runner/workspace/.pythonlibs/lib/python3.11/site-packages/flask/app.py", line 919, in full_dispatch_request
    rv = self.handle_user_exception(e)
         ^^^^^^^^^^^^^^^^^^^^^^^^^^^^^
  File "/home/runner/workspace/.pythonlibs/lib/python3.11/site-packages/flask/app.py", line 917, in full_dispatch_request
    rv = self.dispatch_request()
         ^^^^^^^^^^^^^^^^^^^^^^^
  File "/home/runner/workspace/.pythonlibs/lib/python3.11/site-packages/flask/app.py", line 902, in dispatch_request
    return self.ensure_sync(self.view_functions[rule.endpoint])(**view_args)  # type: ignore[no-any-return]
           ^^^^^^^^^^^^^^^^^^^^^^^^^^^^^^^^^^^^^^^^^^^^^^^^^^^^^^^^^^^^^^^^^^^^^^^^^^^^^^^^^^^^^^^^^^^^^^^^
  File "/home/runner/workspace/web_interface.py", line 53, in dashboard
    return render_template('dashboard.html',
           ^^^^^^^^^^^^^^^^^^^^^^^^^^^^^^^^^
  File "/home/runner/workspace/.pythonlibs/lib/python3.11/site-packages/flask/templating.py", line 149, in render_template
    template = app.jinja_env.get_or_select_template(template_name_or_list)
               ^^^^^^^^^^^^^^^^^^^^^^^^^^^^^^^^^^^^^^^^^^^^^^^^^^^^^^^^^^^
  File "/home/runner/workspace/.pythonlibs/lib/python3.11/site-packages/jinja2/environment.py", line 1087, in get_or_select_template
    return self.get_template(template_name_or_list, parent, globals)
           ^^^^^^^^^^^^^^^^^^^^^^^^^^^^^^^^^^^^^^^^^^^^^^^^^^^^^^^^^
  File "/home/runner/workspace/.pythonlibs/lib/python3.11/site-packages/jinja2/environment.py", line 1016, in get_template
    return self._load_template(name, globals)
           ^^^^^^^^^^^^^^^^^^^^^^^^^^^^^^^^^^
  File "/home/runner/workspace/.pythonlibs/lib/python3.11/site-packages/jinja2/environment.py", line 975, in _load_template
    template = self.loader.load(self, name, self.make_globals(globals))
               ^^^^^^^^^^^^^^^^^^^^^^^^^^^^^^^^^^^^^^^^^^^^^^^^^^^^^^^^
  File "/home/runner/workspace/.pythonlibs/lib/python3.11/site-packages/jinja2/loaders.py", line 138, in load
    code = environment.compile(source, name, filename)
           ^^^^^^^^^^^^^^^^^^^^^^^^^^^^^^^^^^^^^^^^^^^
  File "/home/runner/workspace/.pythonlibs/lib/python3.11/site-packages/jinja2/environment.py", line 771, in compile
    self.handle_exception(source=source_hint)
  File "/home/runner/workspace/.pythonlibs/lib/python3.11/site-packages/jinja2/environment.py", line 942, in handle_exception
    raise rewrite_traceback_stack(source=source)
  File "/home/runner/workspace/templates/dashboard.html", line 364, in template
    const severityData = {{ stats.get('by_severity', {}) | tojsonfilter | safe }};
jinja2.exceptions.TemplateAssertionError: No filter named 'tojsonfilter'.

During handling of the above exception, another exception occurred:

Traceback (most recent call last):
  File "/home/runner/workspace/.pythonlibs/lib/python3.11/site-packages/werkzeug/serving.py", line 370, in run_wsgi
    execute(self.server.app)
  File "/home/runner/workspace/.pythonlibs/lib/python3.11/site-packages/werkzeug/serving.py", line 331, in execute
    application_iter = app(environ, start_response)
                       ^^^^^^^^^^^^^^^^^^^^^^^^^^^^
  File "/home/runner/workspace/.pythonlibs/lib/python3.11/site-packages/flask/app.py", line 1536, in __call__
    return self.wsgi_app(environ, start_response)
           ^^^^^^^^^^^^^^^^^^^^^^^^^^^^^^^^^^^^^^
  File "/home/runner/workspace/.pythonlibs/lib/python3.11/site-packages/flask/app.py", line 1514, in wsgi_app
    response = self.handle_exception(e)
               ^^^^^^^^^^^^^^^^^^^^^^^^
  File "/home/runner/workspace/.pythonlibs/lib/python3.11/site-packages/flask/app.py", line 860, in handle_exception
    server_error = self.ensure_sync(handler)(server_error)
                   ^^^^^^^^^^^^^^^^^^^^^^^^^^^^^^^^^^^^^^^
  File "/home/runner/workspace/web_interface.py", line 425, in internal_error
    return render_template('dashboard.html',
           ^^^^^^^^^^^^^^^^^^^^^^^^^^^^^^^^^
  File "/home/runner/workspace/.pythonlibs/lib/python3.11/site-packages/flask/templating.py", line 149, in render_template
    template = app.jinja_env.get_or_select_template(template_name_or_list)
               ^^^^^^^^^^^^^^^^^^^^^^^^^^^^^^^^^^^^^^^^^^^^^^^^^^^^^^^^^^^
  File "/home/runner/workspace/.pythonlibs/lib/python3.11/site-packages/jinja2/environment.py", line 1087, in get_or_select_template
    return self.get_template(template_name_or_list, parent, globals)
           ^^^^^^^^^^^^^^^^^^^^^^^^^^^^^^^^^^^^^^^^^^^^^^^^^^^^^^^^^
  File "/home/runner/workspace/.pythonlibs/lib/python3.11/site-packages/jinja2/environment.py", line 1016, in get_template
    return self._load_template(name, globals)
           ^^^^^^^^^^^^^^^^^^^^^^^^^^^^^^^^^^
  File "/home/runner/workspace/.pythonlibs/lib/python3.11/site-packages/jinja2/environment.py", line 975, in _load_template
    template = self.loader.load(self, name, self.make_globals(globals))
               ^^^^^^^^^^^^^^^^^^^^^^^^^^^^^^^^^^^^^^^^^^^^^^^^^^^^^^^^
  File "/home/runner/workspace/.pythonlibs/lib/python3.11/site-packages/jinja2/loaders.py", line 138, in load
    code = environment.compile(source, name, filename)
           ^^^^^^^^^^^^^^^^^^^^^^^^^^^^^^^^^^^^^^^^^^^
  File "/home/runner/workspace/.pythonlibs/lib/python3.11/site-packages/jinja2/environment.py", line 771, in compile
    self.handle_exception(source=source_hint)
  File "/home/runner/workspace/.pythonlibs/lib/python3.11/site-packages/jinja2/environment.py", line 942, in handle_exception
    raise rewrite_traceback_stack(source=source)
  File "/home/runner/workspace/templates/dashboard.html", line 364, in template
    const severityData = {{ stats.get('by_severity', {}) | tojsonfilter | safe }};
jinja2.exceptions.TemplateAssertionError: No filter named 'tojsonfilter'.
2025-08-25 12:39:10,599 - publishers.twitter - ERROR - twitter.py:46 - Twitter api_key not configured
2025-08-25 12:39:11,647 - web_interface - ERROR - web_interface.py:311 - Error testing publishers: 400 Bad Request: The browser (or proxy) sent a request that this server could not understand.
2025-08-25 12:39:12,609 - web_interface - ERROR - web_interface.py:311 - Error testing publishers: 400 Bad Request: The browser (or proxy) sent a request that this server could not understand.
2025-08-25 12:41:32,808 - web_interface - ERROR - web_interface.py:226 - Error starting scheduler: signal only works in main thread of the main interpreter
2025-08-25 12:41:40,727 - scheduler - WARNING - scheduler.py:170 - Scheduler is already running
2025-08-25 12:41:45,325 - web_interface - ERROR - web_interface.py:311 - Error testing publishers: 400 Bad Request: The browser (or proxy) sent a request that this server could not understand.
2025-08-25 12:41:48,276 - web_interface - ERROR - web_interface.py:311 - Error testing publishers: 400 Bad Request: The browser (or proxy) sent a request that this server could not understand.
2025-08-25 12:43:41,842 - publishers.twitter - ERROR - twitter.py:46 - Twitter api_key not configured
2025-08-25 12:43:43,974 - web_interface - ERROR - web_interface.py:52 - Error loading dashboard: 0
2025-08-25 12:43:44,723 - web_interface - ERROR - web_interface.py:311 - Error testing publishers: 400 Bad Request: The browser (or proxy) sent a request that this server could not understand.
2025-08-25 12:44:16,481 - web_interface - ERROR - web_interface.py:137 - Error getting stats: 0
2025-08-25 12:44:46,507 - web_interface - ERROR - web_interface.py:137 - Error getting stats: 0
2025-08-25 12:45:16,507 - web_interface - ERROR - web_interface.py:137 - Error getting stats: 0
2025-08-25 12:45:23,593 - publishers.twitter - ERROR - twitter.py:46 - Twitter api_key not configured
2025-08-25 12:45:25,732 - web_interface - ERROR - web_interface.py:52 - Error loading dashboard: 0
2025-08-25 12:45:26,583 - web_interface - ERROR - web_interface.py:311 - Error testing publishers: 400 Bad Request: The browser (or proxy) sent a request that this server could not understand.
2025-08-25 12:45:27,288 - web_interface - ERROR - web_interface.py:52 - Error loading dashboard: 0
2025-08-25 12:45:27,688 - web_interface - ERROR - web_interface.py:311 - Error testing publishers: 400 Bad Request: The browser (or proxy) sent a request that this server could not understand.
2025-08-25 12:45:58,402 - web_interface - ERROR - web_interface.py:137 - Error getting stats: 0
2025-08-25 12:46:02,201 - web_interface - ERROR - web_interface.py:226 - Error starting scheduler: signal only works in main thread of the main interpreter
2025-08-25 12:46:15,998 - web_interface - ERROR - web_interface.py:52 - Error loading dashboard: 0
2025-08-25 12:46:16,918 - web_interface - ERROR - web_interface.py:311 - Error testing publishers: 400 Bad Request: The browser (or proxy) sent a request that this server could not understand.
2025-08-25 12:46:48,766 - web_interface - ERROR - web_interface.py:137 - Error getting stats: 0
2025-08-25 12:47:18,681 - web_interface - ERROR - web_interface.py:137 - Error getting stats: 0
2025-08-25 12:47:48,659 - web_interface - ERROR - web_interface.py:137 - Error getting stats: 0
2025-08-25 12:48:18,773 - web_interface - ERROR - web_interface.py:137 - Error getting stats: 0
2025-08-25 12:48:48,744 - web_interface - ERROR - web_interface.py:137 - Error getting stats: 0
2025-08-25 12:52:10,913 - publishers.twitter - ERROR - twitter.py:46 - Twitter api_key not configured
2025-08-25 12:52:51,584 - publishers.twitter - ERROR - twitter.py:46 - Twitter api_key not configured
2025-08-25 12:52:52,613 - scrapers.base - WARNING - base.py:114 - Request failed (attempt 1/3): 404, message='', url='https://services.nvd.nist.gov/rest/json/cves/2.0?resultsPerPage=2&startIndex=0&lastModStartDate=2025-08-18T12:52:51.000'
2025-08-25 12:52:53,883 - scrapers.base - WARNING - base.py:114 - Request failed (attempt 2/3): 404, message='', url='https://services.nvd.nist.gov/rest/json/cves/2.0?resultsPerPage=2&startIndex=0&lastModStartDate=2025-08-18T12:52:51.000'
2025-08-25 12:52:56,153 - scrapers.base - WARNING - base.py:114 - Request failed (attempt 3/3): 404, message='', url='https://services.nvd.nist.gov/rest/json/cves/2.0?resultsPerPage=2&startIndex=0&lastModStartDate=2025-08-18T12:52:51.000'
2025-08-25 12:52:56,154 - scrapers.base - ERROR - base.py:118 - All retry attempts failed for https://services.nvd.nist.gov/rest/json/cves/2.0
2025-08-25 12:52:56,154 - scrapers.nvd - ERROR - nvd.py:62 - Failed to get response from NVD API
2025-08-25 12:53:15,772 - publishers.twitter - ERROR - twitter.py:46 - Twitter api_key not configured
2025-08-25 12:53:16,849 - __main__ - ERROR - main.py:167 - Error scraping from github: syntax error at or near ":"
LINE 9:                     :cve_id, :vulnerability_id, :title, :des...
                            ^

2025-08-25 12:53:24,044 - publishers.twitter - ERROR - twitter.py:46 - Twitter api_key not configured
2025-08-25 12:54:24,127 - publishers.twitter - ERROR - twitter.py:46 - Twitter api_key not configured
2025-08-25 12:54:33,267 - publishers.twitter - ERROR - twitter.py:46 - Twitter api_key not configured
2025-08-25 12:54:44,856 - publishers.twitter - ERROR - twitter.py:46 - Twitter api_key not configured
2025-08-25 12:54:56,466 - publishers.twitter - ERROR - twitter.py:46 - Twitter api_key not configured
2025-08-25 12:55:23,765 - publishers.twitter - ERROR - twitter.py:46 - Twitter api_key not configured
2025-08-25 12:55:28,484 - content_generator - ERROR - content_generator.py:85 - Error generating summary content: Error code: 429 - {'error': {'message': 'You exceeded your current quota, please check your plan and billing details. For more information on this error, read the docs: https://platform.openai.com/docs/guides/error-codes/api-errors.', 'type': 'insufficient_quota', 'param': None, 'code': 'insufficient_quota'}}
2025-08-25 12:55:54,183 - publishers.twitter - ERROR - twitter.py:46 - Twitter api_key not configured
2025-08-25 12:56:13,965 - publishers.twitter - ERROR - twitter.py:46 - Twitter api_key not configured
2025-08-25 13:03:45,246 - publishers.twitter - ERROR - twitter.py:46 - Twitter api_key not configured
2025-08-25 13:09:47,731 - publishers.twitter - ERROR - twitter.py:46 - Twitter api_key not configured
2025-08-25 13:10:29,949 - publishers.twitter - ERROR - twitter.py:46 - Twitter api_key not configured
2025-08-25 13:16:32,074 - publishers.twitter - ERROR - twitter.py:46 - Twitter api_key not configured
2025-08-25 13:16:40,422 - publishers.twitter - ERROR - twitter.py:46 - Twitter api_key not configured
2025-08-25 13:22:15,454 - publishers.twitter - ERROR - twitter.py:46 - Twitter api_key not configured
2025-08-25 13:22:26,158 - publishers.twitter - ERROR - twitter.py:46 - Twitter api_key not configured
2025-08-25 13:31:32,646 - publishers.twitter - ERROR - twitter.py:46 - Twitter api_key not configured
2025-08-25 13:32:07,219 - publishers.twitter - ERROR - twitter.py:46 - Twitter api_key not configured
2025-08-25 13:40:08,860 - publishers.twitter - ERROR - twitter.py:46 - Twitter api_key not configured
2025-08-26 04:32:59,585 - publishers.twitter - ERROR - twitter.py:46 - Twitter api_key not configured
2025-08-26 05:42:30,453 - publishers.twitter - ERROR - twitter.py:46 - Twitter api_key not configured
2025-08-26 05:42:39,082 - publishers.twitter - ERROR - twitter.py:46 - Twitter api_key not configured
2025-08-26 05:42:41,924 - database - ERROR - database.py:788 - Error getting database stats: 0
2025-08-26 05:42:42,379 - database - ERROR - database.py:851 - Error getting pending review vulnerabilities: syntax error at end of input
LINE 14:             
                     ^

2025-08-26 05:43:22,406 - publishers.twitter - ERROR - twitter.py:46 - Twitter api_key not configured
2025-08-26 05:43:24,823 - database - ERROR - database.py:791 - Error getting database stats: 'DatabaseManager' object has no attribute '_create_tables'
2025-08-26 05:43:25,495 - database - ERROR - database.py:854 - Error getting pending review vulnerabilities: syntax error at end of input
LINE 14:             
                     ^

2025-08-26 06:01:36,471 - scrapers.hackerone - WARNING - hackerone.py:29 - HackerOne credentials not configured, skipping
2025-08-26 06:02:22,773 - scrapers.base - WARNING - base.py:114 - Request failed (attempt 1/3): 404, message='', url='https://services.nvd.nist.gov/rest/json/cves/2.0?resultsPerPage=2000&startIndex=0&lastModStartDate=2025-08-19T06:02:21.000'
2025-08-26 06:02:24,054 - scrapers.base - WARNING - base.py:114 - Request failed (attempt 2/3): 404, message='', url='https://services.nvd.nist.gov/rest/json/cves/2.0?resultsPerPage=2000&startIndex=0&lastModStartDate=2025-08-19T06:02:21.000'
2025-08-26 06:02:26,346 - scrapers.base - WARNING - base.py:114 - Request failed (attempt 3/3): 404, message='', url='https://services.nvd.nist.gov/rest/json/cves/2.0?resultsPerPage=2000&startIndex=0&lastModStartDate=2025-08-19T06:02:21.000'
2025-08-26 06:02:26,346 - scrapers.base - ERROR - base.py:118 - All retry attempts failed for https://services.nvd.nist.gov/rest/json/cves/2.0
2025-08-26 06:02:26,347 - scrapers.nvd - ERROR - nvd.py:62 - Failed to get response from NVD API
2025-08-26 06:06:17,926 - publishers.twitter - ERROR - twitter.py:46 - Twitter api_key not configured
2025-08-26 06:06:20,797 - database - ERROR - database.py:621 - Error getting database stats: 0
